S28800011AAK27GA0000DTS000100SH    0000619200Y
S28800012ABK27GA00000KB001000SSO   0000763800Y
S28800012ABK27GA00000LB001000SSO   0000763600Y
S28800012ABK27GA00000MS001000SSO   0000764800Y
S28800012AAK27GA0000DUS001000SDS   0000549300Y
S28800012AAK27GA0000DVB001000SDS   0000548000Y
S28800012AAK27GA0000DWB000100SPY   0001424100Y
S28800012AAK27GA0000DXS000100SPY   0001426300Y
S28800012AAK27GA0000DYB000100SH    0000618500Y
S28800015AAK27GA0000DZB001000SDS   0000547800Y
S28800075ABK27GA00000NS000100UWM   0000542900Y
S28800075ABK27GA00000OB000100TWM   0000701400Y
S28800075ABK27GA00000PB000100TWM   0000701600Y
S28800075ABK27GA00000QB000100UWM   0000542000Y
S28800075ABK27GA00000RS000100TWM   0000702600Y
S28800075ABK27GA00000SB000100TWM   0000701500Y
S28800136A4K27GA00002RS000100DOG   0000598500Y
S28800137A3K27G6000006S000100DDM   0000802100Y
S28800136A4K27GA00002SS000100DXD   0000501300Y
S28800136A4K27GA00002TS000100DXD   0000501100Y
S28800136A4K27GA00002US000100DXD   0000501200Y
S28800136A4K27GA00002VB000100DXD   0000500400Y
S28800136A4K27GA00002WB000100DOG   0000597200Y
S28800137A3K27G6000007B000100DDM   0000800700Y
S28800161A4K27GA00002XB000100DIG   0001235800Y
S28800161A4K27GA00002YS000100DIG   0001244400Y
S28800160A6K27GA00001IB000100IYE   0001530500Y
S28800160A6K27GA00001JS000100IYE   0001539100Y
S28800162A1K27GA00000VB000100AAPL  0001828600Y
S28800162A1K27GA00000WS000100AAPL  0001834800Y
S28800162A1K27GA00000XB000100AAPL  0001828600Y
S28800162A1K27GA00000YS000100AAPL  0001834800Y
S28800164A9K27G60000CZS001000QID   0000382200Y
S28800164A9K27G60000D0S001000QLD   0000889800Y
S28800164A9K27G60000D1B001000QLD   0000888500Y
S28800164A9K27G60000D2B001000QLD   0000888400Y
S28800164A9K27G60000D3B001000QQQQ  0000495100Y
S28800164A9K27G60000D4B001000QID   0000380900Y
S28800165A9K27G60000D5B000500QQQQ  0000495000Y
S28800165A9K27G60000D6B000500QQQQ  0000494900Y
S28800165A9K27G60000D7B000500QQQQ  0000494400Y
S28800166A9K27G60000D8B000500QQQQ  0000493800Y
S28800166A9K27G60000D9B000500QQQQ  0000494300Y
S28800166A9K27G60000DAB000500QQQQ  0000495100Y
S28800166A9K27G60000DBB000500QQQQ  0000493700Y
S28800166A9K27G60000DCS000500QQQQ  0000496700Y
S28800166A9K27G60000DDS000500QQQQ  0000497300Y
S28800166A9K27G60000DEB000500QQQQ  0000494800Y
S28800166A9K27G60000DFB000500QQQQ  0000494700Y
S28800166A9K27G60000DGB000500QQQQ  0000494100Y
S28800166A9K27G60000DHS000500QQQQ  0000496800Y
S28800166A9K27G60000DIS000500QQQQ  0000497400Y
S28800166A9K27G60000DJB000500QQQQ  0000494500Y
S28800166A9K27G60000DKB000500QQQQ  0000493900Y
S28800166A9K27G60000DLS000500QQQQ  0000496600Y
S28800166A9K27G60000DMS000500QQQQ  0000497200Y
S28800166A9K27G60000DNB000500QQQQ  0000494600Y
S28800166A9K27G60000DOB000500QQQQ  0000494000Y
S28800166A9K27G60000DPS000500QQQQ  0000496400Y
S28800166A9K27G60000DQS000500QQQQ  0000497000Y
S28800166A9K27G60000DRS000500QQQQ  0000497600Y
S28800166A9K27G60000DSB000500QQQQ  0000494200Y
S28800166A9K27G60000DTS000500QQQQ  0000496300Y
S28800166A9K27G60000DUS000500QQQQ  0000496900Y
S28800166A9K27G60000DVS000500QQQQ  0000496500Y
S28800166A9K27G60000DWS000500QQQQ  0000497100Y
S28800166A9K27G60000DXS000500QQQQ  0000497700Y
S28800166A9K27G60000DYS000500QQQQ  0000497500Y
S28800167A4K27GA00002ZB000100DRYS  0001052600Y
S28800168X1K27GA00000Y000100
S28800168A1K27GA00000YS000100AAPL  0001831900Y
S28800168X1K27GA00000V000100
S28800168A1K27GA00000VB000100AAPL  0001826100Y
S28800168X1K27GA00000W000100
S28800168A1K27GA00000WS000100AAPL  0001831900Y
S28800172A9K27G60000DZB001000QQQQ  0000495200Y
S28800172A9K27G60000E0B001000QQQQ  0000495300Y
S28800172A9K27G60000E1B000500QQQQ  0000495200Y
S28800172A9K27G60000E2B000500QQQQ  0000495300Y
S28800173A5K27GA00000JS000100FXP   0000658400Y
S28800174A5K27GA00000KB000100FXP   0000654400Y
S28800174X5K27GA00000K000100
S28800176A5K27GA00000LB000100FXP   0000654200Y
S28800179X5K27GA00000J000100
S28800179A5K27GA00000MB000100FXP   0000656600Y
S28800180X1K27GA00000V000100
S28800180A1K27GA00000VB000100AAPL  0001828600Y
S28800180X1K27GA00000Y000100
S28800180A1K27GA00000YS000100AAPL  0001834800Y
S28800180X1K27GA00000X000100
S28800180A1K27GA00000XB000100AAPL  0001830100Y
S28800180XAK27GA0000DW000100
S28800181X4K27GA00002X000100
S28800179X6K27GA00001I000100
S28800181X1K27GA00000Y000100
S28800181A1K27GA00000YS000100AAPL  0001833400Y
S28800182A9K27G60000E3B001000QQQQ  0000495500Y
S28800182X1K27GA00000Y000100
S28800182A1K27GA00000YS000100AAPL  0001831900Y
S28800183A4K27GA000030B000100DIG   0001235600Y
S28800183AAK27GA0000E0B000100SPY   0001423700Y
S28800182A6K27GA00001KB000100IYE   0001530300Y
S28800185A4K27GA000031B000100DIG   0001237700Y
S28800185X4K27GA000030000100
S28800184A6K27GA00001LB000100IYE   0001531500Y
S28800190ABK27GA00000TS000100UYG   0000322900Y
S28800190A4K27GA000032S000100DRYS  0001071400Y
S28800189A6K27GA00001MS000100IYF   0000860000Y
S28800189A6K27GA00001NS000100IYF   0000859900Y
S28800191A6K27GA00001OB000100IYF   0000853100Y
S28800196A6K27GA00001PS000100IYM   0000877000Y
S28800196A6K27GA00001QB000100IYM   0000869800Y
S28800212A4K27GA000033S000100EEV   0000611400Y
S28800212A4K27GA000034S000100EEM   0001541800Y
S28800272A6K27GA00001RS000100IYR   0000713000Y
S28800274ABK27GA00000UB000100URE   0000371000Y
S28800274ABK27GA00000VS000100URE   0000385600Y
S28800272A6K27GA00001SB000100IYR   0000699000Y
S28800277A9K27G60000E4B001000QLD   0000888600Y
S28800277X9K27G60000D0001000
S28800277X9K27G60000D2001000
S28800277X9K27G60000E3001000
S28800279X9K27G60000E2000500
S28800279X9K27G60000E1000500
S28800279X9K27G60000E0001000
S28800279X9K27G60000DZ001000
S28800279A9K27G60000E5S001000QLD   0000890300Y
S28800279A9K27G60000E6B001000QQQQ  0000495200Y
S28800279A9K27G60000E7S001000QQQQ  0000496100Y
S28800279A9K27G60000E8S001000QQQQ  0000496000Y
S28800279X9K27G60000E8001000
S28800279X9K27G60000E7001000
S28800279A9K27G60000E9B001000QQQQ  0000495300Y
S28800281A9K27G60000EAS000100QID   0000382400Y
S28800282X9K27G60000E6001000
S28800282X9K27G60000D3001000
S28800283A9K27G60000EBS001000QLD   0000890400Y
S28800283X9K27G60000DA000500
S28800283A8K27G6000001S000500MZZ   0000494100Y
S28800284A8K27G6000002B000500MZZ   0000491700Y
S28800284A8K27G6000003S000100MVV   0000809000Y
S28800284A8K27G6000004B000100MVV   0000805900Y
S28800283X4K27GA00002V000100
S28800283A4K27GA000035B000100DXD   0000499600Y
S28800283A4K27GA000036B000100DXD   0000499500Y
S28800285X3K27G6000006000100
S28800285A9K27G60000ECB000500QQQQ  0000493600Y
S28800285A4K27GA000037B000100DXD   0000499700Y
S28800287A3K27G6000008S000100DDM   0000802200Y
S28800297X1K27GA00000Y000100
S28800297A1K27GA00000YS000100AAPL  0001833400Y
S28800301ABK27GA00000WB000100URE   0000372200Y
S28800300X6K27GA00001S000100
S28800300A6K27GA00001TB000100IYR   0000700500Y
S28800311X6K27GA00001T000100
S28800311A6K27GA00001UB000100IYR   0000707000Y
S28800312ABK27GA00000XB000100URE   0000379200Y
S28800318E1K27GA00000X00010000001AQ00001
S28800319X1K27GA00000Y000100
S28800319A1K27GA00000YS000100AAPL  0001831900Y
S28800324X4K27GA00002Z000100
S28800326A4K27GA000038B015000ENCY  0000023300Y
S28800327A4K27GA000039S010930ENCY  0000023500Y
S28800330A8K27G6000005B000500MZZ   0000491800Y
S28800330A3K27G6000009B000100DELL  0000010000Y
S28800340A4K27GA00003AB000100DRYS  0001060800Y
S28800377A6K27GA00001VB000100IYF   0000854200Y
S28800378A6K27GA00001WB000100IYF   0000854100Y
S28800395X5K27GA00000M000100
S28800397A5K27GA00000NB000100FXP   0000656100Y
S28800455X9K27G60000D1001000
S28800457A9K27G60000EDB001000QQQQ  0000495200Y
S28800461X9K27G60000ED001000
S28800499X9K27G60000E4001000
S28800501A9K27G60000EEB001000QLD   0000888400Y
S28800501A9K27G60000EFB001000QQQQ  0000495200Y
S28800511X9K27G60000EF001000
S28800520A9K27G60000EGS000100QLD   0000889700Y
S28800520A9K27G60000EHS001000QQQQ  0000495800Y
S28800520A9K27G60000EIS000500QQQQ  0000496000Y
S28800520A9K27G60000EJS000500QQQQ  0000495900Y
S28800520A9K27G60000EKS000500QQQQ  0000495800Y
S28800531X9K27G60000EI000500
S28800531A9K27G60000ELS001000QQQQ  0000496000Y
S28800531X9K27G60000EH001000
S28800533A9K27G60000EMS001000QQQQ  0000495900Y
S28800561AAK27GA0000E1S000100SKF   0001033900Y
S28800560A6K27GA00001XB000100IYF   0000855100Y
S28800561A6K27GA00001YB000100IYF   0000854900Y
S28800562A6K27GA00001ZB000100IYF   0000854800Y
S28800562X6K27GA00001O000100
S28800582X5K27GA00000N000100
S28800583A5K27GA00000OB000100FXP   0000655800Y
S28800728XAK27GA0000E1000100
S28800727A6K27GA000020B000100IYF   0000855000Y
S28800728AAK27GA0000E2S000100SKF   0001031700Y
S28800728A6K27GA000021B000100IYF   0000855800Y
S28800728X6K27GA00001W000100
S28800729A6K27GA000022B000100IYF   0000855700Y
S28800729X6K27GA00001V000100
S28800758X5K27GA00000O000100
S28800758A5K27GA00000PS000100FXP   0000657300Y
S28801017A6K27GA000023S000100IYF   0000858900Y
S28801018XAK27GA0000E0000100
S28801019AAK27GA0000E3B000100SPY   0001423800Y
S28801019ABK27GA00000YS000100UYG   0000322200Y
S28801018A6K27GA000024S000100IYF   0000860000Y
S28801036AAK27GA0000E4B001000SPY   0001425000Y
S28801036AAK27GA0000E5S001000SPY   0001425200Y
S28801098AAK27GA0000E6S001000SPY   0001425300Y
S28801098AAK27GA0000E7B001000SPY   0001424900Y
S28801105AAK27GA0000E8B001000SPY   0001424800Y
S28801105AAK27GA0000E9S001000SPY   0001425400Y
S28801117AAK27GA0000EAS001000SPY   0001425500Y
S28801117AAK27GA0000EBB001000SPY   0001424700Y
S28801337AAK27GA0000ECB001000SPY   0001425000Y
S28801337AAK27GA0000EDS001000SPY   0001425200Y
S28801435AAK27GA0000EES001000SPY   0001425300Y
S28801435AAK27GA0000EFB001000SPY   0001424900Y
S28801436AAK27GA0000EGS001000SPY   0001425400Y
S28801536AAK27GA0000EHB001000SPY   0001424800Y
S28801537AAK27GA0000EIS001000SPY   0001425500Y
S28801560A9K27G60000ENS002000QQQQ  0000495700Y
S28801560A9K27G60000EOB002000QQQQ  0000495500Y
S28801574AAK27GA0000EJB001000SPY   0001424700Y
S28801660A9K27G60000EPB002000QQQQ  0000495400Y
S28801660A9K27G60000EQS002000QQQQ  0000495800Y
S28801697A9K27G60000ERB005000QQQQ  0000495500Y
S28801697A9K27G60000ESS005000QQQQ  0000495700Y
S28801761A9K27G60000ETS002000QQQQ  0000495900Y
S28801761A9K27G60000EUB002000QQQQ  0000495300Y
S28801797A9K27G60000EVS005000QQQQ  0000495800Y
S28801797A9K27G60000EWB005000QQQQ  0000495400Y
S28801897A9K27G60000EXB005000QQQQ  0000495300Y
S28801897A9K27G60000EYS005000QQQQ  0000495900Y
S28801914A1K27GA000011B000100AAPL  0001828600Y
S28801997A9K27G60000EZB005000QQQQ  0000495200Y
S28801997A9K27G60000F0S005000QQQQ  0000496000Y
S28802100X1K27GA000011000100
S28802100A1K27GA000011B000100AAPL  0001830100Y
S28802322A9K27G60000F1B003200QQQQ  0000495500Y
S28802322A9K27G60000F2S003200QQQQ  0000495700Y
S28802408A6K27GA000025B000500IWM   0000736200Y
S28802408A6K27GA000026S000500IWM   0000736500Y
S28802424A9K27G60000F3B003200QQQQ  0000495400Y
S28802424A9K27G60000F4S003200QQQQ  0000495800Y
S28802439A6K27GA000027B000500IWM   0000736100Y
S28802439A6K27GA000028S000500IWM   0000736600Y
S28802465A9K27G60000F5B003200QQQQ  0000495300Y
S28802465A9K27G60000F6S003200QQQQ  0000495900Y
S28802465X1K27GA000011000100
S28802465A1K27GA000011B000100AAPL  0001828600Y
S28802520X4K27GA00003A000100
S28802522A9K27G60000F7B003200QQQQ  0000495200Y
S28802522A9K27G60000F8S003200QQQQ  0000496000Y
S28802537A4K27GA00003BB000100DRYS  0001065100Y
S28802568X4K27GA00002T000100
S28802568X4K27GA000037000100
S28802568A4K27GA00003CS000100DXD   0000500400Y
S28802570A4K27GA00003DB000100DXD   0000499400Y
S28802575X4K27GA00002W000100
S28802576A4K27GA00003EB000100DOG   0000597100Y
S28802623A9K27G60000F9B003200QQQQ  0000495100Y
S28802623A9K27G60000FAS003200QQQQ  0000496100Y
S28802661XAK27GA0000E5001000
S28802661AAK27GA0000E5S001000SPY   0001425600Y
S28802666XAK27GA0000DV001000
S28802667XBK27GA00000M001000
S28802668AAK27GA0000EKB001000SDS   0000547900Y
S28802669ABK27GA00000ZS001000SSO   0000764900Y
S28802672A6K27GA000029B000500IWM   0000736000Y
S28802672A6K27GA00002AS000500IWM   0000736700Y
S28802676A6K27GA00002BS000500IWM   0000736800Y
S28802676A6K27GA00002CB000500IWM   0000735900Y
S28802682A9K27G60000FBB001000QLD   0000888600Y
S28802682X9K27G60000EE001000
S28802685A9K27G60000FCB001000QQQQ  0000495200Y
S28802688X9K27G60000F2003200
S28802688A9K27G60000F2S003200QQQQ  0000496200Y
S28802688X9K27G60000EZ005000
S28802690A9K27G60000FDB001000QLD   0000888500Y
S28802694A9K27G60000FEB005000QQQQ  0000495600Y
S28802694X9K27G60000FC001000
S28802858AAK27GA0000ELB003000SPY   0001424900Y
S28802858AAK27GA0000EMS003000SPY   0001425400Y
S28802864AAK27GA0000ENB003000SPY   0001424700Y
S28802864AAK27GA0000EOS003000SPY   0001425600Y
S28802866AAK27GA0000EPB003000SPY   0001424500Y
S28802866AAK27GA0000EQS003000SPY   0001425800Y
S28802903XAK27GA0000ED001000
S28802917XAK27GA0000EB001000
S28802917AAK27GA0000EBB001000SPY   0001425100Y
S28802917XAK27GA0000EJ001000
S28802918AAK27GA0000ERS001000SPY   0001425600Y
S28802918AAK27GA0000ESB000900SPY   0001425100Y
S28802918AAK27GA0000ETB003000SPY   0001424900Y
S28802918AAK27GA0000EUS003000SPY   0001425400Y
S28802919AAK27GA0000EVS000100SH    0000619100Y
S28802920XBK27GA00000K001000
S28802920ABK27GA000010B001000SSO   0000763900Y
S28802922XBK27GA00000L001000
S28802922ABK27GA000011B001000SSO   0000763700Y
S28802926AAK27GA0000EWS000500SPY   0001425300Y
S28802926AAK27GA0000EXB000500SPY   0001425000Y
S28802926AAK27GA0000EYS003000SPY   0001425600Y
S28802926AAK27GA0000EZB003000SPY   0001424700Y
S28802953AAK27GA0000F0S003000SPY   0001425800Y
S28802953AAK27GA0000F1B003000SPY   0001424500Y
S28802953AAK27GA0000F2B000500SPY   0001424900Y
S28802953AAK27GA0000F3S000500SPY   0001425400Y
S28802980AAK27GA0000F4S000500SPY   0001425500Y
S28802980AAK27GA0000F5B000500SPY   0001424800Y
S28802995AAK27GA0000F6S000500SPY   0001425600Y
S28802995AAK27GA0000F7B000500SPY   0001424700Y
S28803036XAK27GA0000DY000100
S28803036XAK27GA0000EK001000
S28803036XBK27GA00000Z001000
S28803037AAK27GA0000F8B000100SH    0000618400Y
S28803038AAK27GA0000F9B001000SDS   0000547800Y
S28803038ABK27GA000012S001000SSO   0000765000Y
S28803047XAK27GA0000DZ001000
S28803219A4K27GA00003FS000100DXD   0000500500Y
S28803219A4K27GA00003GS000200DIA   0001298500Y
S28803219A4K27GA00003HB000200DIA   0001298300Y
S28803221A4K27GA00003IS000100DXD   0000500600Y
S28803221A4K27GA00003JB000100DOG   0000597200Y
S28803221A3K27G600000AS000100DDM   0000802100Y
S28803221A4K27GA00003KB000100DXD   0000499700Y
S28803222A4K27GA00003LB000200DIA   0001298200Y
S28803222A4K27GA00003MS000200DIA   0001298600Y
S28803224X3K27G6000008000100
S28803224X3K27G600000A000100
S28803224E4K27GA00003G00007700004AQ00001
S28803224E4K27GA00003G00007600004AQ00002
S28803225X4K27GA00003J000100
S28803226A3K27G600000BS000100DDM   0000802200Y
S28803226X4K27GA00003K000100
S28803228A4K27GA00003PB000100DXD   0000499700Y
S28803234X4K27GA00003P000100
S28803238X4K27GA00003G000047
S28803238A4K27GA00003QB000200DIA   0001298100Y
S28803240P4K27GA00003PB000100DXD   0000499600000N4AQ00003
S28803247X4K27GA00003C000100
S28803247X3K27G6000007000100
S28803247X4K27GA00002R000100
S28803248A4K27GA00003RS000100DXD   0000500700Y
S28803249A3K27G600000CB000100DDM   0000800600Y
S28803249A4K27GA00003SS000100DOG   0000598600Y
S28803685XAK27GA0000F7000500
S28803685AAK27GA0000F7B000500SPY   0001425100Y
S28803869A9K27G60000FFS005000QQQQ  0000495700Y
S28803869A9K27G60000FGB005000QQQQ  0000495500Y
S28803968A9K27G60000FHB005000QQQQ  0000495400Y
S28803968A9K27G60000FIS005000QQQQ  0000495800Y
S28804068A9K27G60000FJB005000QQQQ  0000495300Y
S28804068A9K27G60000FKS005000QQQQ  0000495900Y
S28804168A9K27G60000FLB005000QQQQ  0000495200Y
S28804168A9K27G60000FMS005000QQQQ  0000496000Y
S28804485A4K27GA00003TS000100DOG   0000598500Y
S28804485X4K27GA00002S000100
S28804485A4K27GA00003US000100DXD   0000500400Y
S28804485A3K27G600000DB000100DDM   0000800700Y
S28804999XAK27GA0000EW000500
S28804999AAK27GA0000EWS000500SPY   0001425700Y
S28805083A9K27G60000FNS002000QQQQ  0000495700Y
S28805083A9K27G60000FOB002000QQQQ  0000495500Y
S28805183A9K27G60000FPS002000QQQQ  0000495800Y
S28805614XAK27GA0000EW000500
S28805614AAK27GA0000EWS000500SPY   0001425300Y
S28805824A9K27G60000FQB002000QQQQ  0000495600Y
S28805824X9K27G60000FL005000
S28805825A9K27G60000FRB005000QQQQ  0000495600Y
S28805826X9K27G60000EU002000
S28805826A9K27G60000EUB002000QQQQ  0000495600Y
S28805962A8K27G6000006B002000MSFT  0000282700Y
S28806390A1K27GA000012B002000AMAT  0000182900Y
S28806429A1K27GA000013B002000AMGN  0000413600Y
S28806448A1K27GA000014B002000AMZN  0000796800Y
S28806466A2K27G600000FB002000BRCM  0000259400Y
S28806486A3K27G600000EB002000CELG  0000454800Y
S28806510A3K27G600000FB002000CHKP  0000231700Y
S28806531A3K27G600000GB002000CREE  0000237300Y
S28806556A3K27G600000HB002000CYMI  0000285200Y
S28806574A4K27GA00003VB002000DISH  0000320300Y
S28806603A4K27GA00003WB002000DRIV  0000358300Y
S28806794AAK27GA0000FAB000600SPY   0001419600Y
S28806923AAK27GA0000FBS000100SKF   0001031400Y
S28806923XAK27GA0000E2000100
S28806922A6K27GA00002DB000100IYF   0000855300Y
S28806922X6K27GA00001X000100
S28806923X6K27GA00001Z000100
S28806923A6K27GA00002EB000100IYF   0000855900Y
S28806925AAK27GA0000FCS000500SPY   0001425400Y
S28806925AAK27GA0000FDB000500SPY   0001425000Y
S28806927AAK27GA0000FEB000500SPY   0001424900Y
S28806927AAK27GA0000FFS000500SPY   0001425500Y
S28806928AAK27GA0000FGB000500SPY   0001424800Y
S28806928AAK27GA0000FHS000500SPY   0001425600Y
S28806930AAK27GA0000FIB000500SPY   0001424700Y
S28806930AAK27GA0000FJS000500SPY   0001425700Y
S28806960X1K27GA000011000100
S28806960A1K27GA000011B000100AAPL  0001830100Y
S28807196E5K27GA00000L00002000005AQ00001
S28807197X5K27GA00000P000100
S28807197X5K27GA00000L000080
S28807197A5K27GA00000RS000100FXP   0000657100Y
S28807199A5K27GA00000SB000100FXP   0000654100Y
S28807216E5K27GA00000S00010000005AQ00002
S28807218A5K27GA00000UB000100FXP   0000652500Y
S28807220X5K27GA00000U000100
S28807222A5K27GA00000VB000100FXP   0000652500Y
S28807224X5K27GA00000V000100
S28807225A5K27GA00000WB000100FXP   0000651400Y
S28807226A5K27GA00000XB000100FXP   0000652500Y
S28807239E5K27GA00000X00010000005AQ00003
S28807241X5K27GA00000W000100
S28807242A5K27GA00000ZB000100FXP   0000652300Y
S28807274A4K27GA00003XS000200DIA   0001298700Y
S28807386A4K27GA00003YB002000EBAY  0000292900Y
S28807423A4K27GA00003ZB002000ENZN  0000069500Y
S28807440A5K27GA000010B002000GILD  0000515700Y
S28807456A5K27GA000011B002000IACI  0000220300Y
S28807472A6K27GA00002FB002000IMCL  0000285600Y
S28807478A6K27GA00002GB002000INTC  0000237800Y
S28807492A6K27GA00002HB002000INTU  0000256400Y
S28807506A7K27GA00000KB002000MRVL  0000135200Y
S28807520A8K27G6000007B002000NFLX  0000308000Y
S28807528PCK27GA000016B000177ZVZZT 0020000000000I000HV1PJ
S28807529PCK27GA000016B000100ZVZZT 0020000000000I000HV1PK
S28807529PCK27GA000016B000100ZVZZT 0020000000000I000HV1PL
S28807959AAK27GA0000FKB002000SAP   0000470900Y
S28807982A1K27GA000015B002000A     0000345100Y
S28808228X9K27G60000ES005000
S28808228X9K27G60000FF005000
S28808229X9K27G60000EN002000
S28808229A9K27G60000ENS002000QQQQ  0000496000Y
S28808230A9K27G60000FSS005000QQQQ  0000496100Y
S28808230A9K27G60000FTS005000QQQQ  0000496100Y
S28808393A1K27GA000016B002000AA    0000431500Y
S28808420A9K27G60000FUB002000QCOM  0000457300Y
S28808443A1K27GA000017B002000ADI   0000339700Y
S28808446A4K27GA000040S000047DIA   0001298800Y
S28808453A9K27G60000FVB002000QLGC  0000144200Y
S28808485A1K27GA000018B002000ADP   0000419000Y
S28808495AAK27GA0000FLB002000SHLD  0000604900Y
S28808513A1K27GA000019B002000AIG   0000371800Y
S28808528AAK27GA0000FMB002000SINA  0000507400Y
S28808550AAK27GA0000FNB002000SMTC  0000162200Y
S28808553A1K27GA00001AB002000APA   0001428400Y
S28808590AAK27GA0000FOB002000SOHU  0000796000Y
S28808605A2K27G600000GB002000BAC   0000347300Y
S28808623ABK27GA000013B002000SYMC  0000195200Y
S28808633A2K27G600000HB002000BRL   0000370400Y
S28808654ABK27GA000014B002000TTWO  0000254000Y
S28808666A2K27G600000IB002000C     0000218900Y
S28808720A3K27G600000IB002000COF   0000495200Y
S28808736A4K27GA000041B002000DNA   0000685300Y
S28809385X6K27GA00002F002000
S28809418XAK27GA0000FL002000
S28809425A4K27GA000042B002000DVN   0001208500Y
S28809462ACK27GA000017B002000VSEA  0000373100Y
S28809489A4K27GA000043B002000EMR   0000551000Y
S28809502ACK27GA000018B002000WFMI  0000275300Y
S28809539A5K27GA000012B002000FNM   0000275800Y
S28809539A1K27GA00001BB002000AA    0000432300Y
S28809550ACK27GA000019B002000XLNX  0000254400Y
S28809581A5K27GA000013B002000GG    0000384100Y
S28809606A1K27GA00001CB002000ADI   0000340500Y
S28809644A5K27GA000014B002000GM    0000171100Y
S28809649ACK27GA00001AB002000YHOO  0000265100Y
S28809671A1K27GA00001DB002000ADP   0000419800Y
S28809707A1K27GA00001EB002000AAPL  0001816400Y
S28809708A5K27GA000015B002000GS    0001816500Y
S28809744A1K27GA00001FB002000AIG   0000372600Y
S28809755A6K27GA00002IB002000IBM   0001246600Y
S28809791A1K27GA00001GB002000ADSK  0000384200Y
S28809807A1K27GA00001HB002000APA   0001429200Y
S28809830A6K27GA00002JB002000JNJ   0000638000Y
S28809840A1K27GA00001IB002000ADTN  0000228200Y
S28809877A7K27GA00000LB002000KSS   0000453000Y
S28809892A2K27G600000JB002000BAC   0000348200Y
S28809901A1K27GA00001JB002000ALTR  0000211400Y
S28809928A7K27GA00000MB002000LMT   0000020300Y
S28809989A2K27G600000KB002000C     0000219700Y
S28810016A3K27G600000JB002000COF   0000496000Y
S28810038A4K27GA000044B002000DNA   0000686100Y
S28810393X7K27GA00000M002000
S28810459A7K27GA00000NB002000MDT   0000477800Y
S28810459A4K27GA000045B002000DVN   0001209300Y
S28810461A6K27GA00002KB002000IMCL  0000288900Y
S28810470A7K27GA00000OB002000MMM   0000762000Y
S28810482AAK27GA0000FPS001000SPY   0001425400Y
S28810482AAK27GA0000FQB001000SPY   0001424900Y
S28810482AAK27GA0000FRB002000SHLD  0000610000Y
S28810494A4K27GA000046B002000EMR   0000551800Y
S28810536A7K27GA00000PB002000MO    0000211600Y
S28810538A1K27GA00001KB002000APOL  0000403200Y
S28810579A1K27GA00001LB002000APPX  0000092400Y
S28810581A8K27G6000008B002000NBR   0000402800Y
S28810581A5K27GA000016B002000FNM   0000276600Y
S28810624A2K27G600000LB002000BBBY  0000307500Y
S28810642A5K27GA000017B002000GG    0000384900Y
S28810656A2K27G600000MB002000CAKE  0000193900Y
S28810683A5K27GA000018B002000GM    0000172000Y
S28810685A3K27G600000KB002000CECO  0000107600Y
S28810728A3K27G600000LB002000CEPH  0000645200Y
S28810728A8K27G6000009B002000NEM   0000472800Y
S28810728A5K27GA000019B002000GS    0001817300Y
S28810742A9K27G60000FWB004000QQQQ  0000495400Y
S28810742A9K27G60000FXB004000QQQQ  0000495300Y
S28810742A9K27G60000FYS002000QQQQ  0000495800Y
S28810743A9K27G60000FZS004000QQQQ  0000495900Y
S28810744A9K27G60000G0B002000QQQQ  0000495600Y
S28810744A9K27G60000G1S002000QQQQ  0000495800Y
S28810746A9K27G60000G2B002000QQQQ  0000495500Y
S28810746A9K27G60000G3S002000QQQQ  0000495900Y
S28810747A9K27G60000G4B002000QQQQ  0000495400Y
S28810747A9K27G60000G5S002000QQQQ  0000496000Y
S28810749A9K27G60000G6B002000QQQQ  0000495300Y
S28810749A9K27G60000G7S002000QQQQ  0000496100Y
S28810751A9K27G60000G8B002000QQQQ  0000495200Y
S28810751A9K27G60000G9S002000QQQQ  0000496200Y
S28810783ABK27GA000015B002000TGT   0000515800Y
S28810792A6K27GA00002LB002000IBM   0001247400Y
S28810841ABK27GA000016B002000TXN   0000308200Y
S28810877A6K27GA00002MB002000JNJ   0000638900Y
S28810890ABK27GA000017B002000TYC   0000439100Y
S28810906A7K27GA00000QB002000KSS   0000453800Y
S28810928ABK27GA000018B002000UTX   0000012300Y
S28810958ACK27GA00001BB002000VZ    0000373300Y
S28811393XAK27GA0000FR002000
S28811489A3K27G600000MB002000CCMP  0000354200Y
S28811488A7K27GA00000RB002000LMT   0000027100Y
S28811528A3K27G600000NB002000CMCSA 0000192100Y
S28811547X9K27G60000F9003200
S28811547A9K27G60000F9B003200QQQQ  0000495600Y
S28811549XBK27GA000018002000
S28811550X9K27G60000FN002000
S28811554A9K27G60000GAS002000QQQQ  0000495900Y
S28811554X9K27G60000EB001000
S28811556A9K27G60000GBS001000QQQQ  0000495900Y
S28811556X9K27G60000EL001000
S28811557A7K27GA00000SB002000MDT   0000478600Y
S28811560X9K27G60000GB001000
S28811562A9K27G60000GCS001000QQQQ  0000496000Y
S28811582A3K27G600000OB002000COST  0000693000Y
S28811594A7K27GA00000TB002000LMT   0000026300Y
S28811616A3K27G600000PB002000CSCO  0000251300Y
S28811629ACK27GA00001CB002000WLP   0000500100Y
S28811644A3K27G600000QB002000CTAS  0000281600Y
S28811659A7K27GA00000UB002000MMM   0000762800Y
S28811659ACK27GA00001DB002000WMT   0000534300Y
S28811685A3K27G600000RB002000CYBX  0000139900Y
S28811707A1K27GA00001MB002000ABX   0000393000Y
S28811707A7K27GA00000VB002000MO    0000212400Y
S28811763XAK27GA0000FP001000
S28811765AAK27GA0000FSS001000SPY   0001425500Y
S28811772A8K27G600000AB002000NBR   0000403600Y
S28811775A1K27GA00001NB002000ACE   0000586400Y
S28811800A8K27G600000BB002000NEM   0000473600Y
S28811806A1K27GA00001OB002000ACF   0000117400Y
S28811826ABK27GA000019B002000TGT   0000516700Y
S28811832A1K27GA00001PB002000ACN   0000356600Y
S28811860ABK27GA00001AB002000TXN   0000309000Y
S28811863A1K27GA00001QB002000AFL   0000012600Y
S28811890ABK27GA00001BB002000TYC   0000439900Y
S28812226A6K27GA00002NB002000IWM   0000736100Y
S28812226A6K27GA00002OB002000IWM   0000736000Y
S28812227A6K27GA00002PS002000IWM   0000736600Y
S28812228X9K27G60000FW002000
S28812227A6K27GA00002QS002000IWM   0000736700Y
S28812244A9K27G60000GDB002000QQQQ  0000495400Y
S28812276X9K27G60000GD002000
S28812376X3K27G600000E002000
S28812389X7K27GA00000R002000
S28812416ABK27GA00001CB002000UTX   0000017100Y
S28812425AAK27GA0000FTS001000SPY   0001425400Y
S28812469X6K27GA00002K002000
S28812493AAK27GA0000FUB002000SHLD  0000615100Y
S28812497ACK27GA00001EB002000VZ    0000374100Y
S28812535X9K27G60000GC001000
S28812535A9K27G60000GES001000QQQQ  0000495900Y
S28812542A3K27G600000SB002000DELL  0000192700Y
S28812557ACK27GA00001FB002000WLP   0000500900Y
S28812568X9K27G60000F9003200
S28812568A9K27G60000F9B003200QQQQ  0000495100Y
S28812595A4K27GA000047B002000ESRX  0000648000Y
S28812610ACK27GA00001GB002000WMT   0000535200Y
S28812632AAK27GA0000FVB001000SDS   0000547800Y
S28812639A1K27GA00001RB002000A     0000345900Y
S28812682X7K27GA00000T002000
S28812701A1K27GA00001SB002000ABT   0000011000Y
S28812720A4K27GA000048B002000EXPD  0000442600Y
S28812736ABK27GA00001DB002000UTX   0000016300Y
S28812754A1K27GA00001TB002000ABX   0000393800Y
S28812767A1K27GA00001UB002000ABT   0000010100Y
S28812792A4K27GA000049B002000FFIV  0000262500Y
S28812795X1K27GA00001Q002000
S28812824A1K27GA00001VB002000ACE   0000587200Y
S28812835A4K27GA00004AB002000FISV  0000500200Y
S28812848A1K27GA00001WB002000ALL   0000483400Y
S28812922A1K27GA00001XB002000ANF   0000719100Y
S28813063XAK27GA0000EP003000
S28813063XAK27GA0000EM003000
S28813063AAK27GA0000FWB002000SPY   0001425100Y
S28813063XAK27GA0000E6001000
S28813063AAK27GA0000E6S001000SPY   0001425700Y
S28813063XAK27GA0000FC000500
S28813063AAK27GA0000FCS000500SPY   0001425800Y
S28813063XAK27GA0000E8001000
S28813063AAK27GA0000E8B001000SPY   0001425200Y
S28813063XAK27GA0000FI000500
S28813063AAK27GA0000FIB000500SPY   0001425200Y
S28813063AAK27GA0000FXB003000SPY   0001425200Y
S28813064X9K27G60000G8002000
S28813064A9K27G60000G8B002000QQQQ  0000495600Y
S28813063X4K27GA00003M000200
S28813063X4K27GA00003Q000200
S28813063A4K27GA00003QB000200DIA   0001298500Y
S28813063X4K27GA00003L000200
S28813063A4K27GA00003LB000200DIA   0001298400Y
S28813063X4K27GA00003X000200
S28813063XAK27GA0000EH001000
S28813063XAK27GA0000F5000500
S28813063AAK27GA0000F5B000500SPY   0001425200Y
S28813063XAK27GA0000F1003000
S28813063XAK27GA0000EW000500
S28813063AAK27GA0000EWS000500SPY   0001425700Y
S28813064XAK27GA0000F4000500
S28813064AAK27GA0000F4S000500SPY   0001425800Y
S28813064XAK27GA0000F3000500
S28813064XAK27GA0000EU003000
S28813064XAK27GA0000FT001000
S28813064AAK27GA0000FYB000900SPY   0001424700Y
S28813064XAK27GA0000EG001000
S28813064XAK27GA0000EE001000
S28813064XAK27GA0000FG000500
S28813064AAK27GA0000FGB000500SPY   0001425100Y
S28813064XAK27GA0000E9001000
S28813064AAK27GA0000E9S001000SPY   0001425800Y
S28813064XAK27GA0000FF000500
S28813064AAK27GA0000FFS000500SPY   0001425900Y
S28813064AAK27GA0000FZB003000SPY   0001425200Y
S28813064AAK27GA0000G0B002000SPY   0001425100Y
S28813065X9K27G60000D4001000
S28813064AAK27GA0000G1S003000SPY   0001426000Y
S28813065X9K27G60000E5001000
S28813064AAK27GA0000G2B002000SPY   0001425200Y
S28813065AAK27GA0000G3S001000SDS   0000549200Y
S28813065ABK27GA00001EB001000SSO   0000764000Y
S28813065XBK27GA000010001000
S28813065A4K27GA00004BS000200DIA   0001298900Y
S28813065AAK27GA0000G4S000500SPY   0001425500Y
S28813066X4K27GA00002U000100
S28813066A3K27G600000TB000100DDM   0000800800Y
S28813066A4K27GA00004CS000100DXD   0000500300Y
S28813066AAK27GA0000G5S003000SPY   0001426000Y
S28813066XAK27GA0000FY000900
S28813066AAK27GA0000G6S001000SPY   0001425700Y
S28813066XAK27GA0000FF000500
S28813066AAK27GA0000FFS000500SPY   0001425500Y
S28813066AAK27GA0000G7B000900SPY   0001425200Y
S28813067A9K27G60000GFS001000QQQQ  0000496000Y
S28813067XBK27GA000011001000
S28813067ABK27GA00001FB001000SSO   0000763800Y
S28813067XAK27GA0000F2000500
S28813067AAK27GA0000F2B000500SPY   0001425200Y
S28813068AAK27GA0000G8S001000SPY   0001425800Y
S28813068AAK27GA0000G9S000100SH    0000619000Y
S28813068AAK27GA0000GAS001000SDS   0000549100Y
S28813068XBK27GA00001E001000
S28813068ABK27GA00001GB001000SSO   0000764100Y
S28813069XAK27GA0000F2000500
S28813069AAK27GA0000F2B000500SPY   0001424900Y
S28813069XAK27GA0000E7001000
S28813069AAK27GA0000E7B001000SPY   0001425200Y
S28813070XAK27GA0000EF001000
S28813070AAK27GA0000GBB000900SPY   0001425200Y
S28813070X9K27G60000GF001000
S28813071XBK27GA00001F001000
S28813071ABK27GA00001HB001000SSO   0000763900Y
S28813074X9K27G60000G8002000
S28813074A9K27G60000G8B002000QQQQ  0000495200Y
S28813074A4K27GA00004DS000200DIA   0001299000Y
S28813076XBK27GA000012001000
S28813076XAK27GA0000F9001000
S28813078AAK27GA0000GCB001000SDS   0000547700Y
S28813081XAK27GA0000FE000500
S28813081AAK27GA0000FEB000500SPY   0001425200Y
S28813086XAK27GA0000FV001000
S28813094X4K27GA000040000047
S28813096X9K27G60000F9003200
S28813096A9K27G60000F9B003200QQQQ  0000495600Y
S28813097X9K27G60000FY002000
S28813097A9K27G60000GGS002000QQQQ  0000496000Y
S28813097A9K27G60000GHB002000QQQQ  0000495400Y
S28813097X6K27GA00002C000500
S28813097A6K27GA00002CB000500IWM   0000736300Y
S28813099A9K27G60000GIS002000QQQQ  0000496000Y
S28813098A4K27GA00004ES000047DIA   0001298800Y
S28813101X8K27G6000001000500
S28813099X6K27GA00002P002000
S28813101X8K27G6000004000100
S28813101ABK27GA00001IB000100UWM   0000542100Y
S28813101ABK27GA00001JS000100TWM   0000702400Y
S28813101X8K27G6000005000500
S28813101XBK27GA00000R000100
S28813101X8K27G6000003000100
S28813101X4K27GA00004E000047
S28813103A8K27G600000CS000500MZZ   0000494200Y
S28813103A8K27G600000DB000100MVV   0000805800Y
S28813103A8K27G600000ES000100MVV   0000809100Y
S28813104A4K27GA00004FS000047DIA   0001299100Y
S28813104X4K27GA000035000100
S28813105X3K27G600000B000100
S28813105X4K27GA00003E000100
S28813105X4K27GA000036000100
S28813106A4K27GA00004GB000100DXD   0000499200Y
S28813107A3K27G600000US000100DDM   0000802600Y
S28813105X6K27GA000026000500
S28813105A6K27GA000026S000500IWM   0000736900Y
S28813107A4K27GA00004HB000100DOG   0000597000Y
S28813107A4K27GA00004IB000100DXD   0000499300Y
S28813108XAK27GA0000FS001000
S28813110AAK27GA0000GDS001000SPY   0001425600Y
S28813112X9K27G60000F4003200
S28813112A9K27G60000F4S003200QQQQ  0000496300Y
S28813116X9K27G60000FB001000
S28813116A9K27G60000GJB001000QLD   0000888700Y
S28813116X9K27G60000GJ001000
S28813116A9K27G60000GKB001000QLD   0000888800Y
S28813116A9K27G60000GLS001000QID   0000382100Y
S28813117A3K27G600000VS000100DDM   0000802500Y
S28813118A9K27G60000GMB001000QQQQ  0000495200Y
S28813120X9K27G60000F4003200
S28813120A9K27G60000F4S003200QQQQ  0000495800Y
S28813127X9K27G60000GM001000
S28813127X3K27G600000V000100
S28813127A8K27G600000FS000500MZZ   0000494000Y
S28813127A8K27G600000GB000100MVV   0000806000Y
S28813134X9K27G60000GK001000
S28813134A9K27G60000GNB001000QLD   0000888900Y
S28813135A9K27G60000GOS000100QID   0000382300Y
S28813136A9K27G60000GPB001000QQQQ  0000495200Y
S28813136XAK27GA0000FF000500
S28813136AAK27GA0000FFS000500SPY   0001425900Y
S28813140X9K27G60000GP001000
S28813142X4K27GA00003H000200
S28813142A4K27GA00003HB000200DIA   0001298600Y
S28813144A4K27GA00004JS000100DOG   0000598400Y
S28813144X4K27GA00003R000100
S28813144A4K27GA00004KS000100DXD   0000500200Y
S28813145A3K27G600000WB000100DDM   0000801000Y
S28813149X9K27G60000F4003200
S28813149A9K27G60000F4S003200QQQQ  0000496300Y
S28813151X4K27GA00003L000200
S28813151A4K27GA00003LB000200DIA   0001298700Y
S28813151X4K27GA00004B000200
S28813151XAK27GA0000GD001000
S28813151XAK27GA0000E7001000
S28813151AAK27GA0000E7B001000SPY   0001425300Y
S28813151XAK27GA0000GB000900
S28813151AAK27GA0000GBB000900SPY   0001425300Y
S28813151XAK27GA0000FE000500
S28813151AAK27GA0000FEB000500SPY   0001425300Y
S28813150A6K27GA00002RB002000IWM   0000736200Y
S28813153AAK27GA0000GES001000SPY   0001425700Y
S28813154A3K27G600000XB000100DDM   0000801100Y
S28813154X3K27G600000C000100
S28813154A4K27GA00004LS000200DIA   0001299200Y
S28813170X4K27GA00004L000200
S28813174X4K27GA00003L000200
S28813174A4K27GA00003LB000200DIA   0001298400Y
S28813174A4K27GA00004MS000200DIA   0001298900Y
S28813176X3K27G600000X000100
S28813185X9K27G60000F4003200
S28813185A9K27G60000F4S003200QQQQ  0000495800Y
S28813187XAK27GA0000F2000500
S28813187AAK27GA0000F2B000500SPY   0001425300Y
S28813210AAK27GA0000GFB001000SPY   0001425200Y
S28813210XAK27GA0000FQ001000
S28813215XAK27GA0000F8000100
S28813217XAK27GA0000DX000100
S28813217AAK27GA0000GGB000100SH    0000618300Y
S28813221AAK27GA0000GHS000100SPY   0001426900Y
S28813224XAK27GA0000EY003000
S28813224XAK27GA0000EO003000
S28813224AAK27GA0000GIB002000SPY   0001425300Y
S28813224XAK27GA0000EA001000
S28813224AAK27GA0000EAS001000SPY   0001425900Y
S28813225XAK27GA0000EI001000
S28813225AAK27GA0000GJS003000SPY   0001426200Y
S28813230AAK27GA0000GKS001000SPY   0001425900Y
S28813230AAK27GA0000GLS003000SPY   0001426200Y
S28813246X6K27GA000029000500
S28813246A6K27GA000029B000500IWM   0000736300Y
S28813247X6K27GA000028000500
S28813247A6K27GA000028S000500IWM   0000737000Y
S28813248ABK27GA00001KB000100UWM   0000542300Y
S28813249ABK27GA00001LS000100TWM   0000702200Y
S28813249XBK27GA00001J000100
S28813249X6K27GA000029000500
S28813249A6K27GA000029B000500IWM   0000736000Y
S28813249X6K27GA000028000500
S28813249A6K27GA000028S000500IWM   0000736600Y
S28813251XBK27GA00001K000100
S28813251XBK27GA00001L000100
S28813253ABK27GA00001MS000100TWM   0000702400Y
S28813259X4K27GA00003L000200
S28813259A4K27GA00003LB000200DIA   0001298700Y
S28813259X4K27GA00004M000200
S28813262A3K27G600000YB000100DDM   0000801100Y
S28813264X4K27GA00003L000200
S28813264A4K27GA00003LB000200DIA   0001298400Y
S28813264X4K27GA00003D000100
S28813264A4K27GA00004NS000200DIA   0001298900Y
S28813264X4K27GA00004H000100
S28813265X3K27G600000U000100
S28813266A4K27GA00004OB000100DXD   0000499400Y
S28813266A4K27GA00004PB000100DOG   0000597000Y
S28813267X3K27G600000Y000100
S28813267A3K27G600000ZS000100DDM   0000802600Y
S28813268X6K27GA000029000500
S28813268A6K27GA000029B000500IWM   0000736300Y
S28813271ABK27GA00001NB000100UWM   0000542300Y
S28813271XBK27GA00001M000100
S28813271ABK27GA00001OS000100TWM   0000702200Y
S28813270X6K27GA000029000500
S28813270A6K27GA000029B000500IWM   0000736000Y
S28813272XBK27GA00001N000100
S28813272XBK27GA00001O000100
S28813274ABK27GA00001PS000100TWM   0000702400Y
S28813289XBK27GA00000N000100
S28813289XBK27GA00000O000100
S28813289XBK27GA00000S000100
S28813289XBK27GA00000P000100
S28813288A6K27GA00002SS002000IWM   0000736800Y
S28813291ABK27GA00001QS000100UWM   0000543200Y
S28813290A6K27GA00002TS000100IWM   0000737000Y
S28813290X6K27GA00002T000100
S28813290A6K27GA00002US000100IWM   0000736900Y
S28813295X6K27GA00002U000100
S28813300X9K27G60000EJ000500
S28813300X9K27G60000EK000500
S28813300X9K27G60000EG000100
S28813300A9K27G60000GQB001000QID   0000380800Y
S28813300X9K27G60000EM001000
S28813301X9K27G60000GE001000
S28813302A9K27G60000GRS001000QQQQ  0000496300Y
S28813303A9K27G60000GSS001000QQQQ  0000496000Y
S28813310X9K27G60000GS001000
S28813323XAK27GA0000EC001000
S28813324AAK27GA0000GMB000900SPY   0001425400Y
S28813325AAK27GA0000GNS001000SDS   0000549000Y
S28813325XBK27GA00001G001000
S28813325ABK27GA00001RB001000SSO   0000764200Y
S28813326AAK27GA0000GOS001000SDS   0000549500Y
S28813327XBK27GA00001H001000
S28813327ABK27GA00001SB001000SSO   0000764000Y
S28813432XAK27GA0000FU002000
S28813433XBK27GA00001C002000
S28813441A3K27G6000010B002000CELG  0000457300Y
S28813458X9K27G60000EX005000
S28813458X9K27G60000FJ005000
S28813458X9K27G60000F4003200
S28813458A9K27G60000F4S003200QQQQ  0000496300Y
S28813459A9K27G60000GTB005000QQQQ  0000495700Y
S28813459A9K27G60000GUB005000QQQQ  0000495700Y
S28813461A9K27G60000GVB001000QLD   0000888800Y
S28813474A9K27G60000GWB002000QQQQ  0000495700Y
S28813481X1K27GA00001S002000
S28813486X9K27G60000G1002000
S28813486A9K27G60000G1S002000QQQQ  0000496300Y
S28813486X9K27G60000EP002000
S28813486A9K27G60000EPB002000QQQQ  0000495700Y
S28813496A7K27GA00000WB002000LMT   0000033100Y
S28813497XBK27GA00001D002000
S28813535X1K27GA00001U002000
S28813547A6K27GA00002VB002000IMCL  0000292100Y
S28813555X6K27GA00002Q002000
S28813557A6K27GA00002WS002000IWM   0000736900Y
S28813573X6K27GA000029000500
S28813573A6K27GA000029B000500IWM   0000736400Y
S28813576ABK27GA00001TB000100UWM   0000542300Y
S28813576ABK27GA00001US000100TWM   0000702200Y
S28813576XBK27GA00001P000100
S28813576X6K27GA000029000500
S28813576A6K27GA000029B000500IWM   0000736000Y
S28813578X6K27GA000029000500
S28813578A6K27GA000029B000500IWM   0000736400Y
S28813583A1K27GA00001YB002000ACF   0000118300Y
S28813585X6K27GA000029000500
S28813585A6K27GA000029B000500IWM   0000736000Y
S28813588X8K27G6000002000500
S28813588X8K27G600000E000100
S28813587X6K27GA000029000500
S28813587A6K27GA000029B000500IWM   0000736400Y
S28813589XBK27GA00001T000100
S28813589XBK27GA00001U000100
S28813590A8K27G600000HB000500MZZ   0000491600Y
S28813588X6K27GA000029000500
S28813588A6K27GA000029B000500IWM   0000736000Y
S28813590A8K27G600000IS000100MVV   0000809300Y
S28813591ABK27GA00001VB000100UWM   0000542300Y
S28813591ABK27GA00001WS000100TWM   0000702200Y
S28813591X6K27GA000029000500
S28813591A6K27GA000029B000500IWM   0000736400Y
S28813592XBK27GA00001V000100
S28813592XBK27GA00001W000100
S28813592A4K27GA00004QB002000FITB  0000176600Y
S28813594X8K27G600000F000500
S28813594X8K27G600000G000100
S28813594ABK27GA00001XB000100UWM   0000542300Y
S28813594ABK27GA00001YS000100TWM   0000702200Y
S28813596A8K27G600000JS000500MZZ   0000494100Y
S28813596A8K27G600000KB000100MVV   0000805900Y
S28813596X6K27GA000029000500
S28813596A6K27GA000029B000500IWM   0000736000Y
S28813598X6K27GA000029000500
S28813598A6K27GA000029B000500IWM   0000736400Y
S28813600XBK27GA00001X000100
S28813600XBK27GA00001Y000100
S28813602ABK27GA00001ZS000100TWM   0000702200Y
S28813602ABK27GA000020B000100UWM   0000542300Y
S28813609A8K27G600000LS000500MZZ   0000494000Y
S28813609A8K27G600000MB000100MVV   0000806100Y
S28813615A6K27GA00002XB002000INSP  0000076500Y
S28813638A1K27GA00001ZB002000ACN   0000357400Y
S28813650A6K27GA00002YB002000ISIL  0000274200Y
S28813668A1K27GA000020B002000AFL   0000017100Y
S28813686A6K27GA00002ZB002000JNPR  0000272800Y
S28813713A1K27GA000021B002000ALL   0000484200Y
S28813733A7K27GA00000XB002000LMT   0000032300Y
S28813761A7K27GA00000YB002000KLAC  0000444200Y
S28813772A1K27GA000022B002000ANF   0000719900Y
S28813780A9K27G60000GXB000500QQQQ  0000495100Y
S28813787ABK27GA000021B000100TWM   0000701200Y
S28813787ABK27GA000022B000100TWM   0000701000Y
S28813787ABK27GA000023B000100TWM   0000701100Y
S28813812A1K27GA000023B002000ANN   0000257800Y
S28813837A1K27GA000024B002000AFL   0000016300Y
S28813841A1K27GA000025B002000AOC   0000443100Y
S28813857A1K27GA000026B002000ANN   0000257000Y
S28813867A3K27G6000011S000100DDM   0000802500Y
S28813868A4K27GA00004RB000100DOG   0000597100Y
S28813868A3K27G6000012S000100DDM   0000802400Y
S28813868A4K27GA00004SB000100DXD   0000499500Y
S28813868X4K27GA00004R000100
S28813868X4K27GA00004S000100
S28813869X3K27G6000012000100
S28813879A1K27GA000027B002000AOC   0000442300Y
S28813905A1K27GA000028B002000APC   0000762000Y
S28813928A1K27GA000029B002000ARO   0000291100Y
S28814280X9K27G60000FI005000
S28814280X9K27G60000EV005000
S28814281X9K27G60000G8002000
S28814281A9K27G60000G8B002000QQQQ  0000495700Y
S28814282A9K27G60000GYB004000QQQQ  0000495500Y
S28814282X9K27G60000EQ002000
S28814282A9K27G60000EQS002000QQQQ  0000496100Y
S28814282A9K27G60000GZS005000QQQQ  0000496200Y
S28814282A9K27G60000H0S005000QQQQ  0000496200Y
S28814383X7K27GA00000X002000
S28814399X7K27GA00000W002000
S28814405X1K27GA000020002000
S28814427AAK27GA0000GPB002000SHLD  0000620200Y
S28814432ABK27GA000024B002000UTX   0000021100Y
S28814474X9K27G60000F7003200
S28814474A9K27G60000F7B003200QQQQ  0000495700Y
S28814482A1K27GA00002AB002000ABT   0000014000Y
S28814484X9K27G60000FP002000
S28814512ABK27GA000025B002000UTX   0000020300Y
S28814523A7K27GA00000ZB002000LAMR  0000381700Y
S28814548A1K27GA00002BB002000APC   0000762900Y
S28814564A9K27G60000H1S002000QQQQ  0000496000Y
S28814564X9K27G60000GQ001000
S28814564A9K27G60000H2S001000QQQQ  0000496400Y
S28814566A7K27GA000010B002000LLTC  0000353400Y
S28814608A7K27GA000011B002000LNCR  0000236100Y
S28814609A1K27GA00002CB002000ABT   0000013200Y
S28814624A1K27GA00002DB002000ARO   0000291900Y
S28814654A7K27GA000012B002000LPNT  0000171200Y
S28814667XAK27GA0000GJ003000
S28814675AAK27GA0000GQS003000SPY   0001425600Y
S28814678A2K27G600000NB002000AVP   0000358800Y
S28814678XAK27GA0000GL003000
S28814678AAK27GA0000GRS003000SPY   0001425600Y
S28814691XAK27GA0000GR003000
S28814691XAK27GA0000GQ003000
S28814692X1K27GA000024002000
S28814695AAK27GA0000GSS003000SPY   0001426200Y
S28814695AAK27GA0000GTS003000SPY   0001426200Y
S28814711A7K27GA000013B002000LRCX  0000392200Y
S28814740A2K27G600000OB002000AXP   0000394300Y
S28814782A2K27G600000PB002000AVP   0000358000Y
S28814789A2K27G600000QB002000AZN   0000416400Y
S28814814A2K27G600000RB002000BA    0000851800Y
S28814827A2K27G600000SB002000AXP   0000393500Y
S28814872A2K27G600000TB002000AZN   0000415600Y
S28814887A2K27G600000UB002000BA    0000851000Y
